Workbook

Sheet LEIA-ME
A1: Controle de Verificação – Documentos Fiscais e Bancários (protocolo v2.0)
A3: Legenda de cores
A4: Fundo amarelo | B4: Célula de preenchimento manual.
A5: Fundo cinza-azulado | B5: Fórmula: não editar. Calcula status e gates automaticamente.
A6: Texto azul em itálico | B6: Linha de EXEMPLO. Substitua ou apague antes de usar.
A7: Fundo vermelho / verde | B7: Alerta (hash não confere, revisor = executor, divergência, objeção aberta) / ok.
A9: Abas
A10: Painel | B10: Status de cada item: custódia, testes, revisão cega, divergências, Red Team, veredito, contraditório e se está pronto para revisão jurídica.
A11: Membros_Acesso | B11: Quem tem acesso, em qual célula, conflito de interesse declarado. Use codinomes, nunca nomes reais.
A12: Custodia | B12: Uma linha por arquivo e por versão (F1–F2), com a classe de origem A/B/C (protocolo, seção 4). O Gate F2 só fica 'Sim' com classe, origem (URL e arquivamento, ou referência nos autos quando o canal é 'Processo judicial'), captura, hashes conferidos e dois locais de guarda.
A13: Log_Testes | B13: Cada teste da perícia (F4) e do conteúdo (F5). O revisor cego preenche a coluna M sem ver a coluna H.
A14: Divergencias | B14: Matriz de divergências (F5.2). Diferenças de critério (ex.: custo no IR × valor declarado no TSE) e diferenças dentro da tolerância (aba Parametros) não entram na matriz.
A15: Parametros | B15: Valores definidos no protocolo congelado, como a tolerância de arredondamento. Mudar um valor aqui é desvio de protocolo: registre em ata.
A16: Red_Team | B16: Objeções e explicações inocentes. Nenhum veredito é válido com objeção 'Aberta' para o item.
A17: Atas_Comite | B17: Votos do Comitê sobre cada arquivo. 'Indícios técnicos de alteração' exige 3 votos; os demais, maioria. 'Origem institucional' só vale para item classe A; item classe C só aceita 'Alegação da defesa (classe C)'.
A18: Completude | B18: Testes C1–C6 do módulo F5 (P4). Cole o lacunas_candidatas.csv (ou o completude.csv inteiro) a partir de A2: as colunas A–E batem com o CSV. Depois preencha F (ID do conjunto) e G–K. Revisor cego ≠ analista.
A19: Fontes | B19: Log de cada consulta a fonte pública (guia de fontes, seção 4.4). 'Registro completo?' exige data, coletor, fonte, URL, arquivo local, SHA-256 com 64 caracteres, link arquivado (ou 'não aplicável') e uma ata existente em Atas_Comite. Use o ID F-xxx na coluna 'Fonte primária' da aba Divergencias.
A20: Completude_Conjuntos | B20: Resultado de completude por conjunto (bancário/fiscal), escala da seção 9.3. 'Lacunas não explicadas' exige 3 votos; os demais, maioria. Resultado do Comitê diferente do automático só vale com justificativa em ata.
A21: Contraditorio | B21: Envio aos citados, prazo e resposta. Uma linha por item (repita o envio para cada ID). Status muda sozinho quando o prazo vence.
A22: Listas | B22: Valores das listas suspensas. Pode ampliar, mas não renomear o cabeçalho.
A24: Regras embutidas
A25: Separação de funções | B25: Revisor ≠ executor (Log_Testes) e revisor ≠ analista (Divergencias) são checados automaticamente.
A26: Pronto para publicar | B26: Custódia ok + ao menos 1 teste F4 (dispensado para classe C) + nenhuma revisão pendente ou divergente + nenhuma objeção aberta + veredito válido + contraditório respondido ou com prazo vencido.
A27: Versões | B27: Nova versão de um arquivo = nova linha em Custodia com o mesmo ID e Versão+1. Nunca sobrescreva. O Painel usa a primeira linha do ID.
A29: Segurança
A30: Onde guardar | B30: Esta planilha contém dados sensíveis do processo. Mantenha em armazenamento criptografado com acesso restrito; não compartilhe por link aberto.
A31: Dados pessoais | B31: Não registre CPFs de terceiros, endereços ou dados de dependentes aqui. Referencie o arquivo e a página.
A32: Comandos de hash | B32: macOS/Linux: shasum -a 256 ARQUIVO | shasum -a 512 ARQUIVO · Windows: certutil -hashfile ARQUIVO SHA256

Sheet Painel
A1: Painel de controle – status por item (versão 1 de cada documento)
A2: Digite o ID do item na coluna A (amarela); o restante é calculado a partir das outras abas.
A3: ID item | B3: Tipo | C3: F2 custódia ok? | D3: Testes F4 | E3: Testes F5 | F3: Testes sem revisão cega | G3: Divergências na revisão | H3: Divergências na matriz | I3: Gravidade alta | J3: Objeções abertas | K3: Último veredito | L3: Veredito válido? | M3: Contraditório | N3: Pronto para publicar? | O3: Classe de origem
A4: DOC-001 | B4: =IF(A4="","",IFERROR(INDEX(Custodia!$C$2:$C$301,MATCH(A4,Custodia!$A$2:$A$301,0)),"não custodiado")) | C4: =IF(A4="","",IFERROR(INDEX(Custodia!$S$2:$S$301,MATCH(A4,Custodia!$A$2:$A$301,0)),"NÃO")) | D4: =IF(A4="","",COUNTIFS(Log_Testes!$B$2:$B$301,A4,Log_Testes!$C$2:$C$301,"F4*")) | E4: =IF(A4="","",COUNTIFS(Log_Testes!$B$2:$B$301,A4,Log_Testes!$C$2:$C$301,"F5*")) | F4: =IF(A4="","",COUNTIFS(Log_Testes!$B$2:$B$301,A4,Log_Testes!$A$2:$A$301,"<>",Log_Testes!$M$2:$M$301,"")) | G4: =IF(A4="","",COUNTIFS(Log_Testes!$B$2:$B$301,A4,Log_Testes!$N$2:$N$301,"DIVERGE*")) | H4: =IF(A4="","",COUNTIFS(Divergencias!$B$2:$B$301,A4,Divergencias!$Q$2:$Q$301,"Sim")) | I4: =IF(A4="","",COUNTIFS(Divergencias!$B$2:$B$301,A4,Divergencias!$Q$2:$Q$301,"Sim",Divergencias!$M$2:$M$301,"Alta")) | J4: =IF(A4="","",COUNTIFS(Red_Team!$B$2:$B$301,A4,Red_Team!$I$2:$I$301,"Aberta")) | K4: =IF(A4="","",IFERROR(INDEX(Atas_Comite!$D$2:$D$301,MATCH(A4,Atas_Comite!$P$2:$P$301,0)),"sem ata")) | L4: =IF(A4="","",IFERROR(INDEX(Atas_Comite!$O$2:$O$301,MATCH(A4,Atas_Comite!$P$2:$P$301,0)),"—")) | M4: =IF(A4="","",IFERROR(INDEX(Contraditorio!$M$2:$M$301,MATCH(A4,Contraditorio!$N$2:$N$301,0)),"não enviado")) | N4: =IF(A4="","",IF(AND(C4="Sim",OR(D4>0,LEFT(O4,1)="C"),F4=0,G4=0,J4=0,L4="Sim",OR(M4="Respondido",M4="Prazo encerrado – sem resposta")),"SIM → revisão jurídica","Não")) | O4: =IF(A4="","",IFERROR(INDEX(Custodia!$U$2:$U$301,MATCH(A4,Custodia!$A$2:$A$301,0)),"—"))
B5: =IF(A5="","",IFERROR(INDEX(Custodia!$C$2:$C$301,MATCH(A5,Custodia!$A$2:$A$301,0)),"não custodiado")) | C5: =IF(A5="","",IFERROR(INDEX(Custodia!$S$2:$S$301,MATCH(A5,Custodia!$A$2:$A$301,0)),"NÃO")) | D5: =IF(A5="","",COUNTIFS(Log_Testes!$B$2:$B$301,A5,Log_Testes!$C$2:$C$301,"F4*")) | E5: =IF(A5="","",COUNTIFS(Log_Testes!$B$2:$B$301,A5,Log_Testes!$C$2:$C$301,"F5*")) | F5: =IF(A5="","",COUNTIFS(Log_Testes!$B$2:$B$301,A5,Log_Testes!$A$2:$A$301,"<>",Log_Testes!$M$2:$M$301,"")) | G5: =IF(A5="","",COUNTIFS(Log_Testes!$B$2:$B$301,A5,Log_Testes!$N$2:$N$301,"DIVERGE*")) | H5: =IF(A5="","",COUNTIFS(Divergencias!$B$2:$B$301,A5,Divergencias!$Q$2:$Q$301,"Sim")) | I5: =IF(A5="","",COUNTIFS(Divergencias!$B$2:$B$301,A5,Divergencias!$Q$2:$Q$301,"Sim",Divergencias!$M$2:$M$301,"Alta")) | J5: =IF(A5="","",COUNTIFS(Red_Team!$B$2:$B$301,A5,Red_Team!$I$2:$I$301,"Aberta")) | K5: =IF(A5="","",IFERROR(INDEX(Atas_Comite!$D$2:$D$301,MATCH(A5,Atas_Comite!$P$2:$P$301,0)),"sem ata")) | L5: =IF(A5="","",IFERROR(INDEX(Atas_Comite!$O$2:$O$301,MATCH(A5,Atas_Comite!$P$2:$P$301,0)),"—")) | M5: =IF(A5="","",IFERROR(INDEX(Contraditorio!$M$2:$M$301,MATCH(A5,Contraditorio!$N$2:$N$301,0)),"não enviado")) | N5: =IF(A5="","",IF(AND(C5="Sim",OR(D5>0,LEFT(O5,1)="C"),F5=0,G5=0,J5=0,L5="Sim",OR(M5="Respondido",M5="Prazo encerrado – sem resposta")),"SIM → revisão jurídica","Não")) | O5: =IF(A5="","",IFERROR(INDEX(Custodia!$U$2:$U$301,MATCH(A5,Custodia!$A$2:$A$301,0)),"—"))
B6: =IF(A6="","",IFERROR(INDEX(Custodia!$C$2:$C$301,MATCH(A6,Custodia!$A$2:$A$301,0)),"não custodiado")) | C6: =IF(A6="","",IFERROR(INDEX(Custodia!$S$2:$S$301,MATCH(A6,Custodia!$A$2:$A$301,0)),"NÃO")) | D6: =IF(A6="","",COUNTIFS(Log_Testes!$B$2:$B$301,A6,Log_Testes!$C$2:$C$301,"F4*")) | E6: =IF(A6="","",COUNTIFS(Log_Testes!$B$2:$B$301,A6,Log_Testes!$C$2:$C$301,"F5*")) | F6: =IF(A6="","",COUNTIFS(Log_Testes!$B$2:$B$301,A6,Log_Testes!$A$2:$A$301,"<>",Log_Testes!$M$2:$M$301,"")) | G6: =IF(A6="","",COUNTIFS(Log_Testes!$B$2:$B$301,A6,Log_Testes!$N$2:$N$301,"DIVERGE*")) | H6: =IF(A6="","",COUNTIFS(Divergencias!$B$2:$B$301,A6,Divergencias!$Q$2:$Q$301,"Sim")) | I6: =IF(A6="","",COUNTIFS(Divergencias!$B$2:$B$301,A6,Divergencias!$Q$2:$Q$301,"Sim",Divergencias!$M$2:$M$301,"Alta")) | J6: =IF(A6="","",COUNTIFS(Red_Team!$B$2:$B$301,A6,Red_Team!$I$2:$I$301,"Aberta")) | K6: =IF(A6="","",IFERROR(INDEX(Atas_Comite!$D$2:$D$301,MATCH(A6,Atas_Comite!$P$2:$P$301,0)),"sem ata")) | L6: =IF(A6="","",IFERROR(INDEX(Atas_Comite!$O$2:$O$301,MATCH(A6,Atas_Comite!$P$2:$P$301,0)),"—")) | M6: =IF(A6="","",IFERROR(INDEX(Contraditorio!$M$2:$M$301,MATCH(A6,Contraditorio!$N$2:$N$301,0)),"não enviado")) | N6: =IF(A6="","",IF(AND(C6="Sim",OR(D6>0,LEFT(O6,1)="C"),F6=0,G6=0,J6=0,L6="Sim",OR(M6="Respondido",M6="Prazo encerrado – sem resposta")),"SIM → revisão jurídica","Não")) | O6: =IF(A6="","",IFERROR(INDEX(Custodia!$U$2:$U$301,MATCH(A6,Custodia!$A$2:$A$301,0)),"—"))
B7: =IF(A7="","",IFERROR(INDEX(Custodia!$C$2:$C$301,MATCH(A7,Custodia!$A$2:$A$301,0)),"não custodiado")) | C7: =IF(A7="","",IFERROR(INDEX(Custodia!$S$2:$S$301,MATCH(A7,Custodia!$A$2:$A$301,0)),"NÃO")) | D7: =IF(A7="","",COUNTIFS(Log_Testes!$B$2:$B$301,A7,Log_Testes!$C$2:$C$301,"F4*")) | E7: =IF(A7="","",COUNTIFS(Log_Testes!$B$2:$B$301,A7,Log_Testes!$C$2:$C$301,"F5*")) | F7: =IF(A7="","",COUNTIFS(Log_Testes!$B$2:$B$301,A7,Log_Testes!$A$2:$A$301,"<>",Log_Testes!$M$2:$M$301,"")) | G7: =IF(A7="","",COUNTIFS(Log_Testes!$B$2:$B$301,A7,Log_Testes!$N$2:$N$301,"DIVERGE*")) | H7: =IF(A7="","",COUNTIFS(Divergencias!$B$2:$B$301,A7,Divergencias!$Q$2:$Q$301,"Sim")) | I7: =IF(A7="","",COUNTIFS(Divergencias!$B$2:$B$301,A7,Divergencias!$Q$2:$Q$301,"Sim",Divergencias!$M$2:$M$301,"Alta")) | J7: =IF(A7="","",COUNTIFS(Red_Team!$B$2:$B$301,A7,Red_Team!$I$2:$I$301,"Aberta")) | K7: =IF(A7="","",IFERROR(INDEX(Atas_Comite!$D$2:$D$301,MATCH(A7,Atas_Comite!$P$2:$P$301,0)),"sem ata")) | L7: =IF(A7="","",IFERROR(INDEX(Atas_Comite!$O$2:$O$301,MATCH(A7,Atas_Comite!$P$2:$P$301,0)),"—")) | M7: =IF(A7="","",IFERROR(INDEX(Contraditorio!$M$2:$M$301,MATCH(A7,Contraditorio!$N$2:$N$301,0)),"não enviado")) | N7: =IF(A7="","",IF(AND(C7="Sim",OR(D7>0,LEFT(O7,1)="C"),F7=0,G7=0,J7=0,L7="Sim",OR(M7="Respondido",M7="Prazo encerrado – sem resposta")),"SIM → revisão jurídica","Não")) | O7: =IF(A7="","",IFERROR(INDEX(Custodia!$U$2:$U$301,MATCH(A7,Custodia!$A$2:$A$301,0)),"—"))
B8: =IF(A8="","",IFERROR(INDEX(Custodia!$C$2:$C$301,MATCH(A8,Custodia!$A$2:$A$301,0)),"não custodiado")) | C8: =IF(A8="","",IFERROR(INDEX(Custodia!$S$2:$S$301,MATCH(A8,Custodia!$A$2:$A$301,0)),"NÃO")) | D8: =IF(A8="","",COUNTIFS(Log_Testes!$B$2:$B$301,A8,Log_Testes!$C$2:$C$301,"F4*")) | E8: =IF(A8="","",COUNTIFS(Log_Testes!$B$2:$B$301,A8,Log_Testes!$C$2:$C$301,"F5*")) | F8: =IF(A8="","",COUNTIFS(Log_Testes!$B$2:$B$301,A8,Log_Testes!$A$2:$A$301,"<>",Log_Testes!$M$2:$M$301,"")) | G8: =IF(A8="","",COUNTIFS(Log_Testes!$B$2:$B$301,A8,Log_Testes!$N$2:$N$301,"DIVERGE*")) | H8: =IF(A8="","",COUNTIFS(Divergencias!$B$2:$B$301,A8,Divergencias!$Q$2:$Q$301,"Sim")) | I8: =IF(A8="","",COUNTIFS(Divergencias!$B$2:$B$301,A8,Divergencias!$Q$2:$Q$301,"Sim",Divergencias!$M$2:$M$301,"Alta")) | J8: =IF(A8="","",COUNTIFS(Red_Team!$B$2:$B$301,A8,Red_Team!$I$2:$I$301,"Aberta")) | K8: =IF(A8="","",IFERROR(INDEX(Atas_Comite!$D$2:$D$301,MATCH(A8,Atas_Comite!$P$2:$P$301,0)),"sem ata")) | L8: =IF(A8="","",IFERROR(INDEX(Atas_Comite!$O$2:$O$301,MATCH(A8,Atas_Comite!$P$2:$P$301,0)),"—")) | M8: =IF(A8="","",IFERROR(INDEX(Contraditorio!$M$2:$M$301,MATCH(A8,Contraditorio!$N$2:$N$301,0)),"não enviado")) | N8: =IF(A8="","",IF(AND(C8="Sim",OR(D8>0,LEFT(O8,1)="C"),F8=0,G8=0,J8=0,L8="Sim",OR(M8="Respondido",M8="Prazo encerrado – sem resposta")),"SIM → revisão jurídica","Não")) | O8: =IF(A8="","",IFERROR(INDEX(Custodia!$U$2:$U$301,MATCH(A8,Custodia!$A$2:$A$301,0)),"—"))
B9: =IF(A9="","",IFERROR(INDEX(Custodia!$C$2:$C$301,MATCH(A9,Custodia!$A$2:$A$301,0)),"não custodiado")) | C9: =IF(A9="","",IFERROR(INDEX(Custodia!$S$2:$S$301,MATCH(A9,Custodia!$A$2:$A$301,0)),"NÃO")) | D9: =IF(A9="","",COUNTIFS(Log_Testes!$B$2:$B$301,A9,Log_Testes!$C$2:$C$301,"F4*")) | E9: =IF(A9="","",COUNTIFS(Log_Testes!$B$2:$B$301,A9,Log_Testes!$C$2:$C$301,"F5*")) | F9: =IF(A9="","",COUNTIFS(Log_Testes!$B$2:$B$301,A9,Log_Testes!$A$2:$A$301,"<>",Log_Testes!$M$2:$M$301,"")) | G9: =IF(A9="","",COUNTIFS(Log_Testes!$B$2:$B$301,A9,Log_Testes!$N$2:$N$301,"DIVERGE*")) | H9: =IF(A9="","",COUNTIFS(Divergencias!$B$2:$B$301,A9,Divergencias!$Q$2:$Q$301,"Sim")) | I9: =IF(A9="","",COUNTIFS(Divergencias!$B$2:$B$301,A9,Divergencias!$Q$2:$Q$301,"Sim",Divergencias!$M$2:$M$301,"Alta")) | J9: =IF(A9="","",COUNTIFS(Red_Team!$B$2:$B$301,A9,Red_Team!$I$2:$I$301,"Aberta")) | K9: =IF(A9="","",IFERROR(INDEX(Atas_Comite!$D$2:$D$301,MATCH(A9,Atas_Comite!$P$2:$P$301,0)),"sem ata")) | L9: =IF(A9="","",IFERROR(INDEX(Atas_Comite!$O$2:$O$301,MATCH(A9,Atas_Comite!$P$2:$P$301,0)),"—")) | M9: =IF(A9="","",IFERROR(INDEX(Contraditorio!$M$2:$M$301,MATCH(A9,Contraditorio!$N$2:$N$301,0)),"não enviado")) | N9: =IF(A9="","",IF(AND(C9="Sim",OR(D9>0,LEFT(O9,1)="C"),F9=0,G9=0,J9=0,L9="Sim",OR(M9="Respondido",M9="Prazo encerrado – sem resposta")),"SIM → revisão jurídica","Não")) | O9: =IF(A9="","",IFERROR(INDEX(Custodia!$U$2:$U$301,MATCH(A9,Custodia!$A$2:$A$301,0)),"—"))
B10: =IF(A10="","",IFERROR(INDEX(Custodia!$C$2:$C$301,MATCH(A10,Custodia!$A$2:$A$301,0)),"não custodiado")) | C10: =IF(A10="","",IFERROR(INDEX(Custodia!$S$2:$S$301,MATCH(A10,Custodia!$A$2:$A$301,0)),"NÃO")) | D10: =IF(A10="","",COUNTIFS(Log_Testes!$B$2:$B$301,A10,Log_Testes!$C$2:$C$301,"F4*")) | E10: =IF(A10="","",COUNTIFS(Log_Testes!$B$2:$B$301,A10,Log_Testes!$C$2:$C$301,"F5*")) | F10: =IF(A10="","",COUNTIFS(Log_Testes!$B$2:$B$301,A10,Log_Testes!$A$2:$A$301,"<>",Log_Testes!$M$2:$M$301,"")) | G10: =IF(A10="","",COUNTIFS(Log_Testes!$B$2:$B$301,A10,Log_Testes!$N$2:$N$301,"DIVERGE*")) | H10: =IF(A10="","",COUNTIFS(Divergencias!$B$2:$B$301,A10,Divergencias!$Q$2:$Q$301,"Sim")) | I10: =IF(A10="","",COUNTIFS(Divergencias!$B$2:$B$301,A10,Divergencias!$Q$2:$Q$301,"Sim",Divergencias!$M$2:$M$301,"Alta")) | J10: =IF(A10="","",COUNTIFS(Red_Team!$B$2:$B$301,A10,Red_Team!$I$2:$I$301,"Aberta")) | K10: =IF(A10="","",IFERROR(INDEX(Atas_Comite!$D$2:$D$301,MATCH(A10,Atas_Comite!$P$2:$P$301,0)),"sem ata")) | L10: =IF(A10="","",IFERROR(INDEX(Atas_Comite!$O$2:$O$301,MATCH(A10,Atas_Comite!$P$2:$P$301,0)),"—")) | M10: =IF(A10="","",IFERROR(INDEX(Contraditorio!$M$2:$M$301,MATCH(A10,Contraditorio!$N$2:$N$301,0)),"não enviado")) | N10: =IF(A10="","",IF(AND(C10="Sim",OR(D10>0,LEFT(O10,1)="C"),F10=0,G10=0,J10=0,L10="Sim",OR(M10="Respondido",M10="Prazo encerrado – sem resposta")),"SIM → revisão jurídica","Não")) | O10: =IF(A10="","",IFERROR(INDEX(Custodia!$U$2:$U$301,MATCH(A10,Custodia!$A$2:$A$301,0)),"—"))
B11: =IF(A11="","",IFERROR(INDEX(Custodia!$C$2:$C$301,MATCH(A11,Custodia!$A$2:$A$301,0)),"não custodiado")) | C11: =IF(A11="","",IFERROR(INDEX(Custodia!$S$2:$S$301,MATCH(A11,Custodia!$A$2:$A$301,0)),"NÃO")) | D11: =IF(A11="","",COUNTIFS(Log_Testes!$B$2:$B$301,A11,Log_Testes!$C$2:$C$301,"F4*")) | E11: =IF(A11="","",COUNTIFS(Log_Testes!$B$2:$B$301,A11,Log_Testes!$C$2:$C$301,"F5*")) | F11: =IF(A11="","",COUNTIFS(Log_Testes!$B$2:$B$301,A11,Log_Testes!$A$2:$A$301,"<>",Log_Testes!$M$2:$M$301,"")) | G11: =IF(A11="","",COUNTIFS(Log_Testes!$B$2:$B$301,A11,Log_Testes!$N$2:$N$301,"DIVERGE*")) | H11: =IF(A11="","",COUNTIFS(Divergencias!$B$2:$B$301,A11,Divergencias!$Q$2:$Q$301,"Sim")) | I11: =IF(A11="","",COUNTIFS(Divergencias!$B$2:$B$301,A11,Divergencias!$Q$2:$Q$301,"Sim",Divergencias!$M$2:$M$301,"Alta")) | J11: =IF(A11="","",COUNTIFS(Red_Team!$B$2:$B$301,A11,Red_Team!$I$2:$I$301,"Aberta")) | K11: =IF(A11="","",IFERROR(INDEX(Atas_Comite!$D$2:$D$301,MATCH(A11,Atas_Comite!$P$2:$P$301,0)),"sem ata")) | L11: =IF(A11="","",IFERROR(INDEX(Atas_Comite!$O$2:$O$301,MATCH(A11,Atas_Comite!$P$2:$P$301,0)),"—")) | M11: =IF(A11="","",IFERROR(INDEX(Contraditorio!$M$2:$M$301,MATCH(A11,Contraditorio!$N$2:$N$301,0)),"não enviado")) | N11: =IF(A11="","",IF(AND(C11="Sim",OR(D11>0,LEFT(O11,1)="C"),F11=0,G11=0,J11=0,L11="Sim",OR(M11="Respondido",M11="Prazo encerrado – sem resposta")),"SIM → revisão jurídica","Não")) | O11: =IF(A11="","",IFERROR(INDEX(Custodia!$U$2:$U$301,MATCH(A11,Custodia!$A$2:$A$301,0)),"—"))
B12: =IF(A12="","",IFERROR(INDEX(Custodia!$C$2:$C$301,MATCH(A12,Custodia!$A$2:$A$301,0)),"não custodiado")) | C12: =IF(A12="","",IFERROR(INDEX(Custodia!$S$2:$S$301,MATCH(A12,Custodia!$A$2:$A$301,0)),"NÃO")) | D12: =IF(A12="","",COUNTIFS(Log_Testes!$B$2:$B$301,A12,Log_Testes!$C$2:$C$301,"F4*")) | E12: =IF(A12="","",COUNTIFS(Log_Testes!$B$2:$B$301,A12,Log_Testes!$C$2:$C$301,"F5*")) | F12: =IF(A12="","",COUNTIFS(Log_Testes!$B$2:$B$301,A12,Log_Testes!$A$2:$A$301,"<>",Log_Testes!$M$2:$M$301,"")) | G12: =IF(A12="","",COUNTIFS(Log_Testes!$B$2:$B$301,A12,Log_Testes!$N$2:$N$301,"DIVERGE*")) | H12: =IF(A12="","",COUNTIFS(Divergencias!$B$2:$B$301,A12,Divergencias!$Q$2:$Q$301,"Sim")) | I12: =IF(A12="","",COUNTIFS(Divergencias!$B$2:$B$301,A12,Divergencias!$Q$2:$Q$301,"Sim",Divergencias!$M$2:$M$301,"Alta")) | J12: =IF(A12="","",COUNTIFS(Red_Team!$B$2:$B$301,A12,Red_Team!$I$2:$I$301,"Aberta")) | K12: =IF(A12="","",IFERROR(INDEX(Atas_Comite!$D$2:$D$301,MATCH(A12,Atas_Comite!$P$2:$P$301,0)),"sem ata")) | L12: =IF(A12="","",IFERROR(INDEX(Atas_Comite!$O$2:$O$301,MATCH(A12,Atas_Comite!$P$2:$P$301,0)),"—")) | M12: =IF(A12="","",IFERROR(INDEX(Contraditorio!$M$2:$M$301,MATCH(A12,Contraditorio!$N$2:$N$301,0)),"não enviado")) | N12: =IF(A12="","",IF(AND(C12="Sim",OR(D12>0,LEFT(O12,1)="C"),F12=0,G12=0,J12=0,L12="Sim",OR(M12="Respondido",M12="Prazo encerrado – sem resposta")),"SIM → revisão jurídica","Não")) | O12: =IF(A12="","",IFERROR(INDEX(Custodia!$U$2:$U$301,MATCH(A12,Custodia!$A$2:$A$301,0)),"—"))
B13: =IF(A13="","",IFERROR(INDEX(Custodia!$C$2:$C$301,MATCH(A13,Custodia!$A$2:$A$301,0)),"não custodiado")) | C13: =IF(A13="","",IFERROR(INDEX(Custodia!$S$2:$S$301,MATCH(A13,Custodia!$A$2:$A$301,0)),"NÃO")) | D13: =IF(A13="","",COUNTIFS(Log_Testes!$B$2:$B$301,A13,Log_Testes!$C$2:$C$301,"F4*")) | E13: =IF(A13="","",COUNTIFS(Log_Testes!$B$2:$B$301,A13,Log_Testes!$C$2:$C$301,"F5*")) | F13: =IF(A13="","",COUNTIFS(Log_Testes!$B$2:$B$301,A13,Log_Testes!$A$2:$A$301,"<>",Log_Testes!$M$2:$M$301,"")) | G13: =IF(A13="","",COUNTIFS(Log_Testes!$B$2:$B$301,A13,Log_Testes!$N$2:$N$301,"DIVERGE*")) | H13: =IF(A13="","",COUNTIFS(Divergencias!$B$2:$B$301,A13,Divergencias!$Q$2:$Q$301,"Sim")) | I13: =IF(A13="","",COUNTIFS(Divergencias!$B$2:$B$301,A13,Divergencias!$Q$2:$Q$301,"Sim",Divergencias!$M$2:$M$301,"Alta")) | J13: =IF(A13="","",COUNTIFS(Red_Team!$B$2:$B$301,A13,Red_Team!$I$2:$I$301,"Aberta")) | K13: =IF(A13="","",IFERROR(INDEX(Atas_Comite!$D$2:$D$301,MATCH(A13,Atas_Comite!$P$2:$P$301,0)),"sem ata")) | L13: =IF(A13="","",IFERROR(INDEX(Atas_Comite!$O$2:$O$301,MATCH(A13,Atas_Comite!$P$2:$P$301,0)),"—")) | M13: =IF(A13="","",IFERROR(INDEX(Contraditorio!$M$2:$M$301,MATCH(A13,Contraditorio!$N$2:$N$301,0)),"não enviado")) | N13: =IF(A13="","",IF(AND(C13="Sim",OR(D13>0,LEFT(O13,1)="C"),F13=0,G13=0,J13=0,L13="Sim",OR(M13="Respondido",M13="Prazo encerrado – sem resposta")),"SIM → revisão jurídica","Não")) | O13: =IF(A13="","",IFERROR(INDEX(Custodia!$U$2:$U$301,MATCH(A13,Custodia!$A$2:$A$301,0)),"—"))
B14: =IF(A14="","",IFERROR(INDEX(Custodia!$C$2:$C$301,MATCH(A14,Custodia!$A$2:$A$301,0)),"não custodiado")) | C14: =IF(A14="","",IFERROR(INDEX(Custodia!$S$2:$S$301,MATCH(A14,Custodia!$A$2:$A$301,0)),"NÃO")) | D14: =IF(A14="","",COUNTIFS(Log_Testes!$B$2:$B$301,A14,Log_Testes!$C$2:$C$301,"F4*")) | E14: =IF(A14="","",COUNTIFS(Log_Testes!$B$2:$B$301,A14,Log_Testes!$C$2:$C$301,"F5*")) | F14: =IF(A14="","",COUNTIFS(Log_Testes!$B$2:$B$301,A14,Log_Testes!$A$2:$A$301,"<>",Log_Testes!$M$2:$M$301,"")) | G14: =IF(A14="","",COUNTIFS(Log_Testes!$B$2:$B$301,A14,Log_Testes!$N$2:$N$301,"DIVERGE*")) | H14: =IF(A14="","",COUNTIFS(Divergencias!$B$2:$B$301,A14,Divergencias!$Q$2:$Q$301,"Sim")) | I14: =IF(A14="","",COUNTIFS(Divergencias!$B$2:$B$301,A14,Divergencias!$Q$2:$Q$301,"Sim",Divergencias!$M$2:$M$301,"Alta")) | J14: =IF(A14="","",COUNTIFS(Red_Team!$B$2:$B$301,A14,Red_Team!$I$2:$I$301,"Aberta")) | K14: =IF(A14="","",IFERROR(INDEX(Atas_Comite!$D$2:$D$301,MATCH(A14,Atas_Comite!$P$2:$P$301,0)),"sem ata")) | L14: =IF(A14="","",IFERROR(INDEX(Atas_Comite!$O$2:$O$301,MATCH(A14,Atas_Comite!$P$2:$P$301,0)),"—")) | M14: =IF(A14="","",IFERROR(INDEX(Contraditorio!$M$2:$M$301,MATCH(A14,Contraditorio!$N$2:$N$301,0)),"não enviado")) | N14: =IF(A14="","",IF(AND(C14="Sim",OR(D14>0,LEFT(O14,1)="C"),F14=0,G14=0,J14=0,L14="Sim",OR(M14="Respondido",M14="Prazo encerrado – sem resposta")),"SIM → revisão jurídica","Não")) | O14: =IF(A14="","",IFERROR(INDEX(Custodia!$U$2:$U$301,MATCH(A14,Custodia!$A$2:$A$301,0)),"—"))
B15: =IF(A15="","",IFERROR(INDEX(Custodia!$C$2:$C$301,MATCH(A15,Custodia!$A$2:$A$301,0)),"não custodiado")) | C15: =IF(A15="","",IFERROR(INDEX(Custodia!$S$2:$S$301,MATCH(A15,Custodia!$A$2:$A$301,0)),"NÃO")) | D15: =IF(A15="","",COUNTIFS(Log_Testes!$B$2:$B$301,A15,Log_Testes!$C$2:$C$301,"F4*")) | E15: =IF(A15="","",COUNTIFS(Log_Testes!$B$2:$B$301,A15,Log_Testes!$C$2:$C$301,"F5*")) | F15: =IF(A15="","",COUNTIFS(Log_Testes!$B$2:$B$301,A15,Log_Testes!$A$2:$A$301,"<>",Log_Testes!$M$2:$M$301,"")) | G15: =IF(A15="","",COUNTIFS(Log_Testes!$B$2:$B$301,A15,Log_Testes!$N$2:$N$301,"DIVERGE*")) | H15: =IF(A15="","",COUNTIFS(Divergencias!$B$2:$B$301,A15,Divergencias!$Q$2:$Q$301,"Sim")) | I15: =IF(A15="","",COUNTIFS(Divergencias!$B$2:$B$301,A15,Divergencias!$Q$2:$Q$301,"Sim",Divergencias!$M$2:$M$301,"Alta")) | J15: =IF(A15="","",COUNTIFS(Red_Team!$B$2:$B$301,A15,Red_Team!$I$2:$I$301,"Aberta")) | K15: =IF(A15="","",IFERROR(INDEX(Atas_Comite!$D$2:$D$301,MATCH(A15,Atas_Comite!$P$2:$P$301,0)),"sem ata")) | L15: =IF(A15="","",IFERROR(INDEX(Atas_Comite!$O$2:$O$301,MATCH(A15,Atas_Comite!$P$2:$P$301,0)),"—")) | M15: =IF(A15="","",IFERROR(INDEX(Contraditorio!$M$2:$M$301,MATCH(A15,Contraditorio!$N$2:$N$301,0)),"não enviado")) | N15: =IF(A15="","",IF(AND(C15="Sim",OR(D15>0,LEFT(O15,1)="C"),F15=0,G15=0,J15=0,L15="Sim",OR(M15="Respondido",M15="Prazo encerrado – sem resposta")),"SIM → revisão jurídica","Não")) | O15: =IF(A15="","",IFERROR(INDEX(Custodia!$U$2:$U$301,MATCH(A15,Custodia!$A$2:$A$301,0)),"—"))
B16: =IF(A16="","",IFERROR(INDEX(Custodia!$C$2:$C$301,MATCH(A16,Custodia!$A$2:$A$301,0)),"não custodiado")) | C16: =IF(A16="","",IFERROR(INDEX(Custodia!$S$2:$S$301,MATCH(A16,Custodia!$A$2:$A$301,0)),"NÃO")) | D16: =IF(A16="","",COUNTIFS(Log_Testes!$B$2:$B$301,A16,Log_Testes!$C$2:$C$301,"F4*")) | E16: =IF(A16="","",COUNTIFS(Log_Testes!$B$2:$B$301,A16,Log_Testes!$C$2:$C$301,"F5*")) | F16: =IF(A16="","",COUNTIFS(Log_Testes!$B$2:$B$301,A16,Log_Testes!$A$2:$A$301,"<>",Log_Testes!$M$2:$M$301,"")) | G16: =IF(A16="","",COUNTIFS(Log_Testes!$B$2:$B$301,A16,Log_Testes!$N$2:$N$301,"DIVERGE*")) | H16: =IF(A16="","",COUNTIFS(Divergencias!$B$2:$B$301,A16,Divergencias!$Q$2:$Q$301,"Sim")) | I16: =IF(A16="","",COUNTIFS(Divergencias!$B$2:$B$301,A16,Divergencias!$Q$2:$Q$301,"Sim",Divergencias!$M$2:$M$301,"Alta")) | J16: =IF(A16="","",COUNTIFS(Red_Team!$B$2:$B$301,A16,Red_Team!$I$2:$I$301,"Aberta")) | K16: =IF(A16="","",IFERROR(INDEX(Atas_Comite!$D$2:$D$301,MATCH(A16,Atas_Comite!$P$2:$P$301,0)),"sem ata")) | L16: =IF(A16="","",IFERROR(INDEX(Atas_Comite!$O$2:$O$301,MATCH(A16,Atas_Comite!$P$2:$P$301,0)),"—")) | M16: =IF(A16="","",IFERROR(INDEX(Contraditorio!$M$2:$M$301,MATCH(A16,Contraditorio!$N$2:$N$301,0)),"não enviado")) | N16: =IF(A16="","",IF(AND(C16="Sim",OR(D16>0,LEFT(O16,1)="C"),F16=0,G16=0,J16=0,L16="Sim",OR(M16="Respondido",M16="Prazo encerrado – sem resposta")),"SIM → revisão jurídica","Não")) | O16: =IF(A16="","",IFERROR(INDEX(Custodia!$U$2:$U$301,MATCH(A16,Custodia!$A$2:$A$301,0)),"—"))
... B103: =IF(A103="","",IFERROR(INDEX(Custodia!$C$2:$C$301,MATCH(A103,Custodia!$A$2:$A$301,0)),"não custodiado")) | C103: =IF(A103="","",IFERROR(INDEX(Custodia!$S$2:$S$301,MATCH(A103,Custodia!$A$2:$A$301,0)),"NÃO")) | D103: =IF(A103="","",COUNTIFS(Log_Testes!$B$2:$B$301,A103,Log_Testes!$C$2:$C$301,"F4*")) | E103: =IF(A103="","",COUNTIFS(Log_Testes!$B$2:$B$301,A103,Log_Testes!$C$2:$C$301,"F5*")) | F103: =IF(A103="","",COUNTIFS(Log_Testes!$B$2:$B$301,A103,Log_Testes!$A$2:$A$301,"<>",Log_Testes!$M$2:$M$301,"")) | G103: =IF(A103="","",COUNTIFS(Log_Testes!$B$2:$B$301,A103,Log_Testes!$N$2:$N$301,"DIVERGE*")) | H103: =IF(A103="","",COUNTIFS(Divergencias!$B$2:$B$301,A103,Divergencias!$Q$2:$Q$301,"Sim")) | I103: =IF(A103="","",COUNTIFS(Divergencias!$B$2:$B$301,A103,Divergencias!$Q$2:$Q$301,"Sim",Divergencias!$M$2:$M$301,"Alta")) | J103: =IF(A103="","",COUNTIFS(Red_Team!$B$2:$B$301,A103,Red_Team!$I$2:$I$301,"Aberta")) | K103: =IF(A103="","",IFERROR(INDEX(Atas_Comite!$D$2:$D$301,MATCH(A103,Atas_Comite!$P$2:$P$301,0)),"sem ata")) | L103: =IF(A103="","",IFERROR(INDEX(Atas_Comite!$O$2:$O$301,MATCH(A103,Atas_Comite!$P$2:$P$301,0)),"—")) | M103: =IF(A103="","",IFERROR(INDEX(Contraditorio!$M$2:$M$301,MATCH(A103,Contraditorio!$N$2:$N$301,0)),"não enviado")) | N103: =IF(A103="","",IF(AND(C103="Sim",OR(D103>0,LEFT(O103,1)="C"),F103=0,G103=0,J103=0,L103="Sim",OR(M103="Respondido",M103="Prazo encerrado – sem resposta")),"SIM → revisão jurídica","Não")) | O103: =IF(A103="","",IFERROR(INDEX(Custodia!$U$2:$U$301,MATCH(A103,Custodia!$A$2:$A$301,0)),"—"))

Sheet Membros_Acesso
A1: Codinome | B1: Célula | C1: Papel | D1: Conflito de interesse declarado? | E1: Descrição do conflito | F1: Pode decidir veredito? | G1: Acesso concedido em | H1: Acesso revogado em | I1: Acesso ativo? | J1: Observações
A2: M01 (EXEMPLO – substituir) | B2: Perícia técnica | C2: Analista técnico | D2: Não | F2: =IF(A2="","",IF(D2="Sim","Não – conflito",IF(B2="Comitê de Método","Sim","Não – fora do Comitê"))) | G2: 46317 | I2: =IF(A2="","",IF(H2="","Sim","Não"))
F3: =IF(A3="","",IF(D3="Sim","Não – conflito",IF(B3="Comitê de Método","Sim","Não – fora do Comitê"))) | I3: =IF(A3="","",IF(H3="","Sim","Não"))
F4: =IF(A4="","",IF(D4="Sim","Não – conflito",IF(B4="Comitê de Método","Sim","Não – fora do Comitê"))) | I4: =IF(A4="","",IF(H4="","Sim","Não"))
F5: =IF(A5="","",IF(D5="Sim","Não – conflito",IF(B5="Comitê de Método","Sim","Não – fora do Comitê"))) | I5: =IF(A5="","",IF(H5="","Sim","Não"))
F6: =IF(A6="","",IF(D6="Sim","Não – conflito",IF(B6="Comitê de Método","Sim","Não – fora do Comitê"))) | I6: =IF(A6="","",IF(H6="","Sim","Não"))
F7: =IF(A7="","",IF(D7="Sim","Não – conflito",IF(B7="Comitê de Método","Sim","Não – fora do Comitê"))) | I7: =IF(A7="","",IF(H7="","Sim","Não"))
F8: =IF(A8="","",IF(D8="Sim","Não – conflito",IF(B8="Comitê de Método","Sim","Não – fora do Comitê"))) | I8: =IF(A8="","",IF(H8="","Sim","Não"))
F9: =IF(A9="","",IF(D9="Sim","Não – conflito",IF(B9="Comitê de Método","Sim","Não – fora do Comitê"))) | I9: =IF(A9="","",IF(H9="","Sim","Não"))
F10: =IF(A10="","",IF(D10="Sim","Não – conflito",IF(B10="Comitê de Método","Sim","Não – fora do Comitê"))) | I10: =IF(A10="","",IF(H10="","Sim","Não"))
F11: =IF(A11="","",IF(D11="Sim","Não – conflito",IF(B11="Comitê de Método","Sim","Não – fora do Comitê"))) | I11: =IF(A11="","",IF(H11="","Sim","Não"))
F12: =IF(A12="","",IF(D12="Sim","Não – conflito",IF(B12="Comitê de Método","Sim","Não – fora do Comitê"))) | I12: =IF(A12="","",IF(H12="","Sim","Não"))
F13: =IF(A13="","",IF(D13="Sim","Não – conflito",IF(B13="Comitê de Método","Sim","Não – fora do Comitê"))) | I13: =IF(A13="","",IF(H13="","Sim","Não"))
F14: =IF(A14="","",IF(D14="Sim","Não – conflito",IF(B14="Comitê de Método","Sim","Não – fora do Comitê"))) | I14: =IF(A14="","",IF(H14="","Sim","Não"))
... F301: =IF(A301="","",IF(D301="Sim","Não – conflito",IF(B301="Comitê de Método","Sim","Não – fora do Comitê"))) | I301: =IF(A301="","",IF(H301="","Sim","Não"))

Sheet Custodia
A1: ID item | B1: Versão | C1: Tipo de documento | D1: Ano-calendário | E1: Descrição | F1: Canal de divulgação | G1: URL de origem | H1: URL arquivada (archive.org / archive.today) | I1: Data/hora da publicação original | J1: Data/hora da captura | K1: Capturado por (codinome) | L1: SHA-256 | M1: SHA-512 | N1: Local do original (WORM) | O1: Local da 2ª cópia | P1: Carimbo de tempo (OTS/ICP) | Q1: SHA-256 da cópia de trabalho | R1: Hash confere? | S1: Gate F2 ok? | T1: Observações | U1: Classe de origem (A/B/C) | V1: Referência nos autos (processo, ID, fls.)
A2: DOC-001 | B2: 1 | C2: IRPF – PDF | D2: 2025 | E2: Declaração IRPF divulgada (EXEMPLO – substituir) | F2: Site oficial | G2: https://exemplo.invalid/declaracao.pdf | H2: https://web.archive.org/web/... | I2: 46315.604 | J2: 46317.385 | K2: M02 | L2: e3b0c44298fc1c149afbf4c8996fb92427ae41e4649b934ca495991b7852b855 | M2: (colar SHA-512) | N2: bucket-custodia/DOC-001-v1 | O2: disco-cripto-02/DOC-001-v1 | P2: DOC-001-v1.pdf.ots | Q2: e3b0c44298fc1c149afbf4c8996fb92427ae41e4649b934ca495991b7852b855 | R2: =IF(OR(L2="",Q2=""),"",IF(EXACT(LOWER(TRIM(L2)),LOWER(TRIM(Q2))),"Sim","NÃO")) | S2: =IF(A2="","",IF(AND(R2="Sim",U2<>"",IF(F2="Processo judicial",V2<>"",AND(G2<>"",H2<>"")),J2<>"",K2<>"",N2<>"",O2<>""),"Sim","Pendente")) | U2: B – Juntado pelo titular | V2: não se aplica (divulgação pública)
R3: =IF(OR(L3="",Q3=""),"",IF(EXACT(LOWER(TRIM(L3)),LOWER(TRIM(Q3))),"Sim","NÃO")) | S3: =IF(A3="","",IF(AND(R3="Sim",U3<>"",IF(F3="Processo judicial",V3<>"",AND(G3<>"",H3<>"")),J3<>"",K3<>"",N3<>"",O3<>""),"Sim","Pendente"))
R4: =IF(OR(L4="",Q4=""),"",IF(EXACT(LOWER(TRIM(L4)),LOWER(TRIM(Q4))),"Sim","NÃO")) | S4: =IF(A4="","",IF(AND(R4="Sim",U4<>"",IF(F4="Processo judicial",V4<>"",AND(G4<>"",H4<>"")),J4<>"",K4<>"",N4<>"",O4<>""),"Sim","Pendente"))
R5: =IF(OR(L5="",Q5=""),"",IF(EXACT(LOWER(TRIM(L5)),LOWER(TRIM(Q5))),"Sim","NÃO")) | S5: =IF(A5="","",IF(AND(R5="Sim",U5<>"",IF(F5="Processo judicial",V5<>"",AND(G5<>"",H5<>"")),J5<>"",K5<>"",N5<>"",O5<>""),"Sim","Pendente"))
R6: =IF(OR(L6="",Q6=""),"",IF(EXACT(LOWER(TRIM(L6)),LOWER(TRIM(Q6))),"Sim","NÃO")) | S6: =IF(A6="","",IF(AND(R6="Sim",U6<>"",IF(F6="Processo judicial",V6<>"",AND(G6<>"",H6<>"")),J6<>"",K6<>"",N6<>"",O6<>""),"Sim","Pendente"))
R7: =IF(OR(L7="",Q7=""),"",IF(EXACT(LOWER(TRIM(L7)),LOWER(TRIM(Q7))),"Sim","NÃO")) | S7: =IF(A7="","",IF(AND(R7="Sim",U7<>"",IF(F7="Processo judicial",V7<>"",AND(G7<>"",H7<>"")),J7<>"",K7<>"",N7<>"",O7<>""),"Sim","Pendente"))
R8: =IF(OR(L8="",Q8=""),"",IF(EXACT(LOWER(TRIM(L8)),LOWER(TRIM(Q8))),"Sim","NÃO")) | S8: =IF(A8="","",IF(AND(R8="Sim",U8<>"",IF(F8="Processo judicial",V8<>"",AND(G8<>"",H8<>"")),J8<>"",K8<>"",N8<>"",O8<>""),"Sim","Pendente"))
R9: =IF(OR(L9="",Q9=""),"",IF(EXACT(LOWER(TRIM(L9)),LOWER(TRIM(Q9))),"Sim","NÃO")) | S9: =IF(A9="","",IF(AND(R9="Sim",U9<>"",IF(F9="Processo judicial",V9<>"",AND(G9<>"",H9<>"")),J9<>"",K9<>"",N9<>"",O9<>""),"Sim","Pendente"))
R10: =IF(OR(L10="",Q10=""),"",IF(EXACT(LOWER(TRIM(L10)),LOWER(TRIM(Q10))),"Sim","NÃO")) | S10: =IF(A10="","",IF(AND(R10="Sim",U10<>"",IF(F10="Processo judicial",V10<>"",AND(G10<>"",H10<>"")),J10<>"",K10<>"",N10<>"",O10<>""),"Sim","Pendente"))
R11: =IF(OR(L11="",Q11=""),"",IF(EXACT(LOWER(TRIM(L11)),LOWER(TRIM(Q11))),"Sim","NÃO")) | S11: =IF(A11="","",IF(AND(R11="Sim",U11<>"",IF(F11="Processo judicial",V11<>"",AND(G11<>"",H11<>"")),J11<>"",K11<>"",N11<>"",O11<>""),"Sim","Pendente"))
R12: =IF(OR(L12="",Q12=""),"",IF(EXACT(LOWER(TRIM(L12)),LOWER(TRIM(Q12))),"Sim","NÃO")) | S12: =IF(A12="","",IF(AND(R12="Sim",U12<>"",IF(F12="Processo judicial",V12<>"",AND(G12<>"",H12<>"")),J12<>"",K12<>"",N12<>"",O12<>""),"Sim","Pendente"))
R13: =IF(OR(L13="",Q13=""),"",IF(EXACT(LOWER(TRIM(L13)),LOWER(TRIM(Q13))),"Sim","NÃO")) | S13: =IF(A13="","",IF(AND(R13="Sim",U13<>"",IF(F13="Processo judicial",V13<>"",AND(G13<>"",H13<>"")),J13<>"",K13<>"",N13<>"",O13<>""),"Sim","Pendente"))
R14: =IF(OR(L14="",Q14=""),"",IF(EXACT(LOWER(TRIM(L14)),LOWER(TRIM(Q14))),"Sim","NÃO")) | S14: =IF(A14="","",IF(AND(R14="Sim",U14<>"",IF(F14="Processo judicial",V14<>"",AND(G14<>"",H14<>"")),J14<>"",K14<>"",N14<>"",O14<>""),"Sim","Pendente"))
... R301: =IF(OR(L301="",Q301=""),"",IF(EXACT(LOWER(TRIM(L301)),LOWER(TRIM(Q301))),"Sim","NÃO")) | S301: =IF(A301="","",IF(AND(R301="Sim",U301<>"",IF(F301="Processo judicial",V301<>"",AND(G301<>"",H301<>"")),J301<>"",K301<>"",N301<>"",O301<>""),"Sim","Pendente"))

Sheet Log_Testes
A1: ID teste | B1: ID item | C1: Fase | D1: Teste | E1: Ferramenta / comando | F1: Executor (codinome) | G1: Data | H1: Resultado | I1: Arquivo com saída bruta | J1: Observação | K1: Explicação alternativa considerada | L1: Revisor cego (codinome) | M1: Resultado da revisão | N1: Concordância | O1: Revisor ≠ executor?
A2: T-001 | B2: DOC-001 | C2: F4.3 Estrutural | D2: Contagem de seções xref (edição incremental) | E2: qpdf --show-xref DOC-001.pdf | F2: M01 | G2: 46318 | H2: Conforme | I2: laudos/DOC-001/T-001_xref.txt | J2: Uma única tabela xref (EXEMPLO – substituir) | K2: n/a | L2: M03 | M2: Conforme | N2: =IF(OR(H2="",M2=""),"",IF(H2=M2,"Concorda","DIVERGE → Comitê")) | O2: =IF(L2="","",IF(L2<>F2,"Sim","NÃO"))
N3: =IF(OR(H3="",M3=""),"",IF(H3=M3,"Concorda","DIVERGE → Comitê")) | O3: =IF(L3="","",IF(L3<>F3,"Sim","NÃO"))
N4: =IF(OR(H4="",M4=""),"",IF(H4=M4,"Concorda","DIVERGE → Comitê")) | O4: =IF(L4="","",IF(L4<>F4,"Sim","NÃO"))
N5: =IF(OR(H5="",M5=""),"",IF(H5=M5,"Concorda","DIVERGE → Comitê")) | O5: =IF(L5="","",IF(L5<>F5,"Sim","NÃO"))
N6: =IF(OR(H6="",M6=""),"",IF(H6=M6,"Concorda","DIVERGE → Comitê")) | O6: =IF(L6="","",IF(L6<>F6,"Sim","NÃO"))
N7: =IF(OR(H7="",M7=""),"",IF(H7=M7,"Concorda","DIVERGE → Comitê")) | O7: =IF(L7="","",IF(L7<>F7,"Sim","NÃO"))
N8: =IF(OR(H8="",M8=""),"",IF(H8=M8,"Concorda","DIVERGE → Comitê")) | O8: =IF(L8="","",IF(L8<>F8,"Sim","NÃO"))
N9: =IF(OR(H9="",M9=""),"",IF(H9=M9,"Concorda","DIVERGE → Comitê")) | O9: =IF(L9="","",IF(L9<>F9,"Sim","NÃO"))
N10: =IF(OR(H10="",M10=""),"",IF(H10=M10,"Concorda","DIVERGE → Comitê")) | O10: =IF(L10="","",IF(L10<>F10,"Sim","NÃO"))
N11: =IF(OR(H11="",M11=""),"",IF(H11=M11,"Concorda","DIVERGE → Comitê")) | O11: =IF(L11="","",IF(L11<>F11,"Sim","NÃO"))
N12: =IF(OR(H12="",M12=""),"",IF(H12=M12,"Concorda","DIVERGE → Comitê")) | O12: =IF(L12="","",IF(L12<>F12,"Sim","NÃO"))
N13: =IF(OR(H13="",M13=""),"",IF(H13=M13,"Concorda","DIVERGE → Comitê")) | O13: =IF(L13="","",IF(L13<>F13,"Sim","NÃO"))
N14: =IF(OR(H14="",M14=""),"",IF(H14=M14,"Concorda","DIVERGE → Comitê")) | O14: =IF(L14="","",IF(L14<>F14,"Sim","NÃO"))
... N301: =IF(OR(H301="",M301=""),"",IF(H301=M301,"Concorda","DIVERGE → Comitê")) | O301: =IF(L301="","",IF(L301<>F301,"Sim","NÃO"))

Sheet Divergencias
A1: ID | B1: ID item | C1: Campo / item analisado | D1: Valor no documento (R$) | E1: Valor na fonte (R$) | F1: Diferença (R$) | G1: Diferença (%) | H1: Fonte primária | I1: URL / referência | J1: Data da consulta | K1: Diferença de critério? | L1: Explicação possível | M1: Gravidade | N1: Analista | O1: Revisor | P1: Revisor ≠ analista? | Q1: Entra na matriz?
A2: D-001 | B2: DOC-001 | C2: Rendimentos tributáveis – Senado Federal (EXEMPLO – substituir) | D2: 100000 | E2: 100000 | F2: =IF(OR(D2="",E2=""),"",D2-E2) | G2: =IF(OR(D2="",E2="",E2=0),"",(D2-E2)/E2) | H2: Portal da Transparência do Senado | I2: https://... | J2: 46318 | K2: Não | L2: Sem diferença | M2: Baixa | N2: M04 | O2: M05 | P2: =IF(O2="","",IF(O2<>N2,"Sim","NÃO")) | Q2: =IF(A2="","",IF(K2="Sim","Não – critério",IF(AND(ISNUMBER(F2),ABS(F2)<=Parametros!$B$3),"Não – dentro da tolerância",IF(P2="Sim","Sim","Aguarda revisão"))))
F3: =IF(OR(D3="",E3=""),"",D3-E3) | G3: =IF(OR(D3="",E3="",E3=0),"",(D3-E3)/E3) | P3: =IF(O3="","",IF(O3<>N3,"Sim","NÃO")) | Q3: =IF(A3="","",IF(K3="Sim","Não – critério",IF(AND(ISNUMBER(F3),ABS(F3)<=Parametros!$B$3),"Não – dentro da tolerância",IF(P3="Sim","Sim","Aguarda revisão"))))
F4: =IF(OR(D4="",E4=""),"",D4-E4) | G4: =IF(OR(D4="",E4="",E4=0),"",(D4-E4)/E4) | P4: =IF(O4="","",IF(O4<>N4,"Sim","NÃO")) | Q4: =IF(A4="","",IF(K4="Sim","Não – critério",IF(AND(ISNUMBER(F4),ABS(F4)<=Parametros!$B$3),"Não – dentro da tolerância",IF(P4="Sim","Sim","Aguarda revisão"))))
F5: =IF(OR(D5="",E5=""),"",D5-E5) | G5: =IF(OR(D5="",E5="",E5=0),"",(D5-E5)/E5) | P5: =IF(O5="","",IF(O5<>N5,"Sim","NÃO")) | Q5: =IF(A5="","",IF(K5="Sim","Não – critério",IF(AND(ISNUMBER(F5),ABS(F5)<=Parametros!$B$3),"Não – dentro da tolerância",IF(P5="Sim","Sim","Aguarda revisão"))))
F6: =IF(OR(D6="",E6=""),"",D6-E6) | G6: =IF(OR(D6="",E6="",E6=0),"",(D6-E6)/E6) | P6: =IF(O6="","",IF(O6<>N6,"Sim","NÃO")) | Q6: =IF(A6="","",IF(K6="Sim","Não – critério",IF(AND(ISNUMBER(F6),ABS(F6)<=Parametros!$B$3),"Não – dentro da tolerância",IF(P6="Sim","Sim","Aguarda revisão"))))
F7: =IF(OR(D7="",E7=""),"",D7-E7) | G7: =IF(OR(D7="",E7="",E7=0),"",(D7-E7)/E7) | P7: =IF(O7="","",IF(O7<>N7,"Sim","NÃO")) | Q7: =IF(A7="","",IF(K7="Sim","Não – critério",IF(AND(ISNUMBER(F7),ABS(F7)<=Parametros!$B$3),"Não – dentro da tolerância",IF(P7="Sim","Sim","Aguarda revisão"))))
F8: =IF(OR(D8="",E8=""),"",D8-E8) | G8: =IF(OR(D8="",E8="",E8=0),"",(D8-E8)/E8) | P8: =IF(O8="","",IF(O8<>N8,"Sim","NÃO")) | Q8: =IF(A8="","",IF(K8="Sim","Não – critério",IF(AND(ISNUMBER(F8),ABS(F8)<=Parametros!$B$3),"Não – dentro da tolerância",IF(P8="Sim","Sim","Aguarda revisão"))))
F9: =IF(OR(D9="",E9=""),"",D9-E9) | G9: =IF(OR(D9="",E9="",E9=0),"",(D9-E9)/E9) | P9: =IF(O9="","",IF(O9<>N9,"Sim","NÃO")) | Q9: =IF(A9="","",IF(K9="Sim","Não – critério",IF(AND(ISNUMBER(F9),ABS(F9)<=Parametros!$B$3),"Não – dentro da tolerância",IF(P9="Sim","Sim","Aguarda revisão"))))
F10: =IF(OR(D10="",E10=""),"",D10-E10) | G10: =IF(OR(D10="",E10="",E10=0),"",(D10-E10)/E10) | P10: =IF(O10="","",IF(O10<>N10,"Sim","NÃO")) | Q10: =IF(A10="","",IF(K10="Sim","Não – critério",IF(AND(ISNUMBER(F10),ABS(F10)<=Parametros!$B$3),"Não – dentro da tolerância",IF(P10="Sim","Sim","Aguarda revisão"))))
F11: =IF(OR(D11="",E11=""),"",D11-E11) | G11: =IF(OR(D11="",E11="",E11=0),"",(D11-E11)/E11) | P11: =IF(O11="","",IF(O11<>N11,"Sim","NÃO")) | Q11: =IF(A11="","",IF(K11="Sim","Não – critério",IF(AND(ISNUMBER(F11),ABS(F11)<=Parametros!$B$3),"Não – dentro da tolerância",IF(P11="Sim","Sim","Aguarda revisão"))))
F12: =IF(OR(D12="",E12=""),"",D12-E12) | G12: =IF(OR(D12="",E12="",E12=0),"",(D12-E12)/E12) | P12: =IF(O12="","",IF(O12<>N12,"Sim","NÃO")) | Q12: =IF(A12="","",IF(K12="Sim","Não – critério",IF(AND(ISNUMBER(F12),ABS(F12)<=Parametros!$B$3),"Não – dentro da tolerância",IF(P12="Sim","Sim","Aguarda revisão"))))
F13: =IF(OR(D13="",E13=""),"",D13-E13) | G13: =IF(OR(D13="",E13="",E13=0),"",(D13-E13)/E13) | P13: =IF(O13="","",IF(O13<>N13,"Sim","NÃO")) | Q13: =IF(A13="","",IF(K13="Sim","Não – critério",IF(AND(ISNUMBER(F13),ABS(F13)<=Parametros!$B$3),"Não – dentro da tolerância",IF(P13="Sim","Sim","Aguarda revisão"))))
F14: =IF(OR(D14="",E14=""),"",D14-E14) | G14: =IF(OR(D14="",E14="",E14=0),"",(D14-E14)/E14) | P14: =IF(O14="","",IF(O14<>N14,"Sim","NÃO")) | Q14: =IF(A14="","",IF(K14="Sim","Não – critério",IF(AND(ISNUMBER(F14),ABS(F14)<=Parametros!$B$3),"Não – dentro da tolerância",IF(P14="Sim","Sim","Aguarda revisão"))))
... F301: =IF(OR(D301="",E301=""),"",D301-E301) | G301: =IF(OR(D301="",E301="",E301=0),"",(D301-E301)/E301) | P301: =IF(O301="","",IF(O301<>N301,"Sim","NÃO")) | Q301: =IF(A301="","",IF(K301="Sim","Não – critério",IF(AND(ISNUMBER(F301),ABS(F301)<=Parametros!$B$3),"Não – dentro da tolerância",IF(P301="Sim","Sim","Aguarda revisão"))))

Sheet Red_Team
A1: ID objeção | B1: ID item | C1: Ref. teste/divergência | D1: Achado contestado | E1: Explicação inocente proposta | F1: Autor (Red Team) | G1: Resposta técnica | H1: Respondido por | I1: Status | J1: Data
A2: R-001 | B2: DOC-001 | C2: T-001 | D2: Produtor do PDF difere da referência (EXEMPLO – substituir) | E2: Arquivo pode ter sido reexportado por 'Imprimir como PDF' antes da publicação | F2: M06 | G2: Aceito: tratado como perda de rastreabilidade, não adulteração | H2: M01 | I2: Respondida – aceita | J2: 46320

Sheet Atas_Comite
A1: ID ata | B1: Data | C1: ID item | D1: Veredito proposto | E1: Membro 1 | F1: Voto 1 | G1: Membro 2 | H1: Voto 2 | I1: Membro 3 | J1: Voto 3 | K1: Votos a favor | L1: Unânime? | M1: Objeções abertas no Red Team | N1: Justificativa | O1: Veredito válido? | P1: Chave última ata (auxiliar) | Q1: Classe do item (auxiliar)
A2: A-001 | B2: 46321 | C2: DOC-001 | D2: Sem sinais de adulteração, não confirmável | E2: M07 | F2: A favor | G2: M08 | H2: A favor | I2: M09 | J2: A favor | K2: =IF(A2="","",COUNTIF(F2,"A favor")+COUNTIF(H2,"A favor")+COUNTIF(J2,"A favor")) | L2: =IF(A2="","",IF(K2=3,"Sim","Não")) | M2: =IF(C2="","",COUNTIFS(Red_Team!$B$2:$B$301,C2,Red_Team!$I$2:$I$301,"Aberta")) | N2: Testes F4 limpos; sem verificação criptográfica disponível (EXEMPLO – substituir) | O2: =IF(A2="","",IF(M2>0,"NÃO – objeções abertas",IF(AND(D2="Autenticidade confirmada (origem institucional)",Q2<>"A"),"NÃO – exige item classe A",IF(AND(Q2="C",D2<>"Alegação da defesa (classe C)"),"NÃO – item classe C",IF(AND(D2="Alegação da defesa (classe C)",Q2<>"C"),"NÃO – item não é classe C",IF(D2="Indícios técnicos de alteração",IF(L2="Sim","Sim","NÃO – exige unanimidade"),IF(K2>=2,"Sim","NÃO – sem maioria"))))))) | P2: =IF(C2="","",IF(COUNTIF(C3:C$302,C2)=0,C2,"")) | Q2: =IF(C2="","",IFERROR(LEFT(INDEX(Custodia!$U$2:$U$301,MATCH(C2,Custodia!$A$2:$A$301,0)),1),"?"))
K3: =IF(A3="","",COUNTIF(F3,"A favor")+COUNTIF(H3,"A favor")+COUNTIF(J3,"A favor")) | L3: =IF(A3="","",IF(K3=3,"Sim","Não")) | M3: =IF(C3="","",COUNTIFS(Red_Team!$B$2:$B$301,C3,Red_Team!$I$2:$I$301,"Aberta")) | O3: =IF(A3="","",IF(M3>0,"NÃO – objeções abertas",IF(AND(D3="Autenticidade confirmada (origem institucional)",Q3<>"A"),"NÃO – exige item classe A",IF(AND(Q3="C",D3<>"Alegação da defesa (classe C)"),"NÃO – item classe C",IF(AND(D3="Alegação da defesa (classe C)",Q3<>"C"),"NÃO – item não é classe C",IF(D3="Indícios técnicos de alteração",IF(L3="Sim","Sim","NÃO – exige unanimidade"),IF(K3>=2,"Sim","NÃO – sem maioria"))))))) | P3: =IF(C3="","",IF(COUNTIF(C4:C$302,C3)=0,C3,"")) | Q3: =IF(C3="","",IFERROR(LEFT(INDEX(Custodia!$U$2:$U$301,MATCH(C3,Custodia!$A$2:$A$301,0)),1),"?"))
K4: =IF(A4="","",COUNTIF(F4,"A favor")+COUNTIF(H4,"A favor")+COUNTIF(J4,"A favor")) | L4: =IF(A4="","",IF(K4=3,"Sim","Não")) | M4: =IF(C4="","",COUNTIFS(Red_Team!$B$2:$B$301,C4,Red_Team!$I$2:$I$301,"Aberta")) | O4: =IF(A4="","",IF(M4>0,"NÃO – objeções abertas",IF(AND(D4="Autenticidade confirmada (origem institucional)",Q4<>"A"),"NÃO – exige item classe A",IF(AND(Q4="C",D4<>"Alegação da defesa (classe C)"),"NÃO – item classe C",IF(AND(D4="Alegação da defesa (classe C)",Q4<>"C"),"NÃO – item não é classe C",IF(D4="Indícios técnicos de alteração",IF(L4="Sim","Sim","NÃO – exige unanimidade"),IF(K4>=2,"Sim","NÃO – sem maioria"))))))) | P4: =IF(C4="","",IF(COUNTIF(C5:C$302,C4)=0,C4,"")) | Q4: =IF(C4="","",IFERROR(LEFT(INDEX(Custodia!$U$2:$U$301,MATCH(C4,Custodia!$A$2:$A$301,0)),1),"?"))
K5: =IF(A5="","",COUNTIF(F5,"A favor")+COUNTIF(H5,"A favor")+COUNTIF(J5,"A favor")) | L5: =IF(A5="","",IF(K5=3,"Sim","Não")) | M5: =IF(C5="","",COUNTIFS(Red_Team!$B$2:$B$301,C5,Red_Team!$I$2:$I$301,"Aberta")) | O5: =IF(A5="","",IF(M5>0,"NÃO – objeções abertas",IF(AND(D5="Autenticidade confirmada (origem institucional)",Q5<>"A"),"NÃO – exige item classe A",IF(AND(Q5="C",D5<>"Alegação da defesa (classe C)"),"NÃO – item classe C",IF(AND(D5="Alegação da defesa (classe C)",Q5<>"C"),"NÃO – item não é classe C",IF(D5="Indícios técnicos de alteração",IF(L5="Sim","Sim","NÃO – exige unanimidade"),IF(K5>=2,"Sim","NÃO – sem maioria"))))))) | P5: =IF(C5="","",IF(COUNTIF(C6:C$302,C5)=0,C5,"")) | Q5: =IF(C5="","",IFERROR(LEFT(INDEX(Custodia!$U$2:$U$301,MATCH(C5,Custodia!$A$2:$A$301,0)),1),"?"))
K6: =IF(A6="","",COUNTIF(F6,"A favor")+COUNTIF(H6,"A favor")+COUNTIF(J6,"A favor")) | L6: =IF(A6="","",IF(K6=3,"Sim","Não")) | M6: =IF(C6="","",COUNTIFS(Red_Team!$B$2:$B$301,C6,Red_Team!$I$2:$I$301,"Aberta")) | O6: =IF(A6="","",IF(M6>0,"NÃO – objeções abertas",IF(AND(D6="Autenticidade confirmada (origem institucional)",Q6<>"A"),"NÃO – exige item classe A",IF(AND(Q6="C",D6<>"Alegação da defesa (classe C)"),"NÃO – item classe C",IF(AND(D6="Alegação da defesa (classe C)",Q6<>"C"),"NÃO – item não é classe C",IF(D6="Indícios técnicos de alteração",IF(L6="Sim","Sim","NÃO – exige unanimidade"),IF(K6>=2,"Sim","NÃO – sem maioria"))))))) | P6: =IF(C6="","",IF(COUNTIF(C7:C$302,C6)=0,C6,"")) | Q6: =IF(C6="","",IFERROR(LEFT(INDEX(Custodia!$U$2:$U$301,MATCH(C6,Custodia!$A$2:$A$301,0)),1),"?"))
K7: =IF(A7="","",COUNTIF(F7,"A favor")+COUNTIF(H7,"A favor")+COUNTIF(J7,"A favor")) | L7: =IF(A7="","",IF(K7=3,"Sim","Não")) | M7: =IF(C7="","",COUNTIFS(Red_Team!$B$2:$B$301,C7,Red_Team!$I$2:$I$301,"Aberta")) | O7: =IF(A7="","",IF(M7>0,"NÃO – objeções abertas",IF(AND(D7="Autenticidade confirmada (origem institucional)",Q7<>"A"),"NÃO – exige item classe A",IF(AND(Q7="C",D7<>"Alegação da defesa (classe C)"),"NÃO – item classe C",IF(AND(D7="Alegação da defesa (classe C)",Q7<>"C"),"NÃO – item não é classe C",IF(D7="Indícios técnicos de alteração",IF(L7="Sim","Sim","NÃO – exige unanimidade"),IF(K7>=2,"Sim","NÃO – sem maioria"))))))) | P7: =IF(C7="","",IF(COUNTIF(C8:C$302,C7)=0,C7,"")) | Q7: =IF(C7="","",IFERROR(LEFT(INDEX(Custodia!$U$2:$U$301,MATCH(C7,Custodia!$A$2:$A$301,0)),1),"?"))
K8: =IF(A8="","",COUNTIF(F8,"A favor")+COUNTIF(H8,"A favor")+COUNTIF(J8,"A favor")) | L8: =IF(A8="","",IF(K8=3,"Sim","Não")) | M8: =IF(C8="","",COUNTIFS(Red_Team!$B$2:$B$301,C8,Red_Team!$I$2:$I$301,"Aberta")) | O8: =IF(A8="","",IF(M8>0,"NÃO – objeções abertas",IF(AND(D8="Autenticidade confirmada (origem institucional)",Q8<>"A"),"NÃO – exige item classe A",IF(AND(Q8="C",D8<>"Alegação da defesa (classe C)"),"NÃO – item classe C",IF(AND(D8="Alegação da defesa (classe C)",Q8<>"C"),"NÃO – item não é classe C",IF(D8="Indícios técnicos de alteração",IF(L8="Sim","Sim","NÃO – exige unanimidade"),IF(K8>=2,"Sim","NÃO – sem maioria"))))))) | P8: =IF(C8="","",IF(COUNTIF(C9:C$302,C8)=0,C8,"")) | Q8: =IF(C8="","",IFERROR(LEFT(INDEX(Custodia!$U$2:$U$301,MATCH(C8,Custodia!$A$2:$A$301,0)),1),"?"))
K9: =IF(A9="","",COUNTIF(F9,"A favor")+COUNTIF(H9,"A favor")+COUNTIF(J9,"A favor")) | L9: =IF(A9="","",IF(K9=3,"Sim","Não")) | M9: =IF(C9="","",COUNTIFS(Red_Team!$B$2:$B$301,C9,Red_Team!$I$2:$I$301,"Aberta")) | O9: =IF(A9="","",IF(M9>0,"NÃO – objeções abertas",IF(AND(D9="Autenticidade confirmada (origem institucional)",Q9<>"A"),"NÃO – exige item classe A",IF(AND(Q9="C",D9<>"Alegação da defesa (classe C)"),"NÃO – item classe C",IF(AND(D9="Alegação da defesa (classe C)",Q9<>"C"),"NÃO – item não é classe C",IF(D9="Indícios técnicos de alteração",IF(L9="Sim","Sim","NÃO – exige unanimidade"),IF(K9>=2,"Sim","NÃO – sem maioria"))))))) | P9: =IF(C9="","",IF(COUNTIF(C10:C$302,C9)=0,C9,"")) | Q9: =IF(C9="","",IFERROR(LEFT(INDEX(Custodia!$U$2:$U$301,MATCH(C9,Custodia!$A$2:$A$301,0)),1),"?"))
K10: =IF(A10="","",COUNTIF(F10,"A favor")+COUNTIF(H10,"A favor")+COUNTIF(J10,"A favor")) | L10: =IF(A10="","",IF(K10=3,"Sim","Não")) | M10: =IF(C10="","",COUNTIFS(Red_Team!$B$2:$B$301,C10,Red_Team!$I$2:$I$301,"Aberta")) | O10: =IF(A10="","",IF(M10>0,"NÃO – objeções abertas",IF(AND(D10="Autenticidade confirmada (origem institucional)",Q10<>"A"),"NÃO – exige item classe A",IF(AND(Q10="C",D10<>"Alegação da defesa (classe C)"),"NÃO – item classe C",IF(AND(D10="Alegação da defesa (classe C)",Q10<>"C"),"NÃO – item não é classe C",IF(D10="Indícios técnicos de alteração",IF(L10="Sim","Sim","NÃO – exige unanimidade"),IF(K10>=2,"Sim","NÃO – sem maioria"))))))) | P10: =IF(C10="","",IF(COUNTIF(C11:C$302,C10)=0,C10,"")) | Q10: =IF(C10="","",IFERROR(LEFT(INDEX(Custodia!$U$2:$U$301,MATCH(C10,Custodia!$A$2:$A$301,0)),1),"?"))
K11: =IF(A11="","",COUNTIF(F11,"A favor")+COUNTIF(H11,"A favor")+COUNTIF(J11,"A favor")) | L11: =IF(A11="","",IF(K11=3,"Sim","Não")) | M11: =IF(C11="","",COUNTIFS(Red_Team!$B$2:$B$301,C11,Red_Team!$I$2:$I$301,"Aberta")) | O11: =IF(A11="","",IF(M11>0,"NÃO – objeções abertas",IF(AND(D11="Autenticidade confirmada (origem institucional)",Q11<>"A"),"NÃO – exige item classe A",IF(AND(Q11="C",D11<>"Alegação da defesa (classe C)"),"NÃO – item classe C",IF(AND(D11="Alegação da defesa (classe C)",Q11<>"C"),"NÃO – item não é classe C",IF(D11="Indícios técnicos de alteração",IF(L11="Sim","Sim","NÃO – exige unanimidade"),IF(K11>=2,"Sim","NÃO – sem maioria"))))))) | P11: =IF(C11="","",IF(COUNTIF(C12:C$302,C11)=0,C11,"")) | Q11: =IF(C11="","",IFERROR(LEFT(INDEX(Custodia!$U$2:$U$301,MATCH(C11,Custodia!$A$2:$A$301,0)),1),"?"))
K12: =IF(A12="","",COUNTIF(F12,"A favor")+COUNTIF(H12,"A favor")+COUNTIF(J12,"A favor")) | L12: =IF(A12="","",IF(K12=3,"Sim","Não")) | M12: =IF(C12="","",COUNTIFS(Red_Team!$B$2:$B$301,C12,Red_Team!$I$2:$I$301,"Aberta")) | O12: =IF(A12="","",IF(M12>0,"NÃO – objeções abertas",IF(AND(D12="Autenticidade confirmada (origem institucional)",Q12<>"A"),"NÃO – exige item classe A",IF(AND(Q12="C",D12<>"Alegação da defesa (classe C)"),"NÃO – item classe C",IF(AND(D12="Alegação da defesa (classe C)",Q12<>"C"),"NÃO – item não é classe C",IF(D12="Indícios técnicos de alteração",IF(L12="Sim","Sim","NÃO – exige unanimidade"),IF(K12>=2,"Sim","NÃO – sem maioria"))))))) | P12: =IF(C12="","",IF(COUNTIF(C13:C$302,C12)=0,C12,"")) | Q12: =IF(C12="","",IFERROR(LEFT(INDEX(Custodia!$U$2:$U$301,MATCH(C12,Custodia!$A$2:$A$301,0)),1),"?"))
K13: =IF(A13="","",COUNTIF(F13,"A favor")+COUNTIF(H13,"A favor")+COUNTIF(J13,"A favor")) | L13: =IF(A13="","",IF(K13=3,"Sim","Não")) | M13: =IF(C13="","",COUNTIFS(Red_Team!$B$2:$B$301,C13,Red_Team!$I$2:$I$301,"Aberta")) | O13: =IF(A13="","",IF(M13>0,"NÃO – objeções abertas",IF(AND(D13="Autenticidade confirmada (origem institucional)",Q13<>"A"),"NÃO – exige item classe A",IF(AND(Q13="C",D13<>"Alegação da defesa (classe C)"),"NÃO – item classe C",IF(AND(D13="Alegação da defesa (classe C)",Q13<>"C"),"NÃO – item não é classe C",IF(D13="Indícios técnicos de alteração",IF(L13="Sim","Sim","NÃO – exige unanimidade"),IF(K13>=2,"Sim","NÃO – sem maioria"))))))) | P13: =IF(C13="","",IF(COUNTIF(C14:C$302,C13)=0,C13,"")) | Q13: =IF(C13="","",IFERROR(LEFT(INDEX(Custodia!$U$2:$U$301,MATCH(C13,Custodia!$A$2:$A$301,0)),1),"?"))
K14: =IF(A14="","",COUNTIF(F14,"A favor")+COUNTIF(H14,"A favor")+COUNTIF(J14,"A favor")) | L14: =IF(A14="","",IF(K14=3,"Sim","Não")) | M14: =IF(C14="","",COUNTIFS(Red_Team!$B$2:$B$301,C14,Red_Team!$I$2:$I$301,"Aberta")) | O14: =IF(A14="","",IF(M14>0,"NÃO – objeções abertas",IF(AND(D14="Autenticidade confirmada (origem institucional)",Q14<>"A"),"NÃO – exige item classe A",IF(AND(Q14="C",D14<>"Alegação da defesa (classe C)"),"NÃO – item classe C",IF(AND(D14="Alegação da defesa (classe C)",Q14<>"C"),"NÃO – item não é classe C",IF(D14="Indícios técnicos de alteração",IF(L14="Sim","Sim","NÃO – exige unanimidade"),IF(K14>=2,"Sim","NÃO – sem maioria"))))))) | P14: =IF(C14="","",IF(COUNTIF(C15:C$302,C14)=0,C14,"")) | Q14: =IF(C14="","",IFERROR(LEFT(INDEX(Custodia!$U$2:$U$301,MATCH(C14,Custodia!$A$2:$A$301,0)),1),"?"))
... K301: =IF(A301="","",COUNTIF(F301,"A favor")+COUNTIF(H301,"A favor")+COUNTIF(J301,"A favor")) | L301: =IF(A301="","",IF(K301=3,"Sim","Não")) | M301: =IF(C301="","",COUNTIFS(Red_Team!$B$2:$B$301,C301,Red_Team!$I$2:$I$301,"Aberta")) | O301: =IF(A301="","",IF(M301>0,"NÃO – objeções abertas",IF(AND(D301="Autenticidade confirmada (origem institucional)",Q301<>"A"),"NÃO – exige item classe A",IF(AND(Q301="C",D301<>"Alegação da defesa (classe C)"),"NÃO – item classe C",IF(AND(D301="Alegação da defesa (classe C)",Q301<>"C"),"NÃO – item não é classe C",IF(D301="Indícios técnicos de alteração",IF(L301="Sim","Sim","NÃO – exige unanimidade"),IF(K301>=2,"Sim","NÃO – sem maioria"))))))) | P301: =IF(C301="","",IF(COUNTIF(C302:C$302,C301)=0,C301,"")) | Q301: =IF(C301="","",IFERROR(LEFT(INDEX(Custodia!$U$2:$U$301,MATCH(C301,Custodia!$A$2:$A$301,0)),1),"?"))

Sheet Contraditorio
A1: ID | B1: ID item | C1: Destinatário | D1: Canal (e-mail/ofício) | E1: Data/hora do envio | F1: Prazo (horas) | G1: Prazo final | H1: Comprovante de envio | I1: Data/hora da resposta | J1: Resumo da resposta | K1: Originais solicitados? | L1: Originais recebidos? | M1: Status | N1: Chave último envio (auxiliar)
A2: C-001 | B2: DOC-001 | C2: Assessoria do senador (EXEMPLO – substituir) | D2: E-mail oficial | E2: 46322.417 | F2: 72 | G2: =IF(OR(E2="",F2=""),"",E2+F2/24) | H2: contraditorio/C-001_envio.eml | K2: Sim | L2: Não | M2: =IF(A2="","",IF(I2<>"","Respondido",IF(G2="","Sem prazo definido",IF(NOW()>G2,"Prazo encerrado – sem resposta","Aguardando")))) | N2: =IF(B2="","",IF(COUNTIF(B3:B$302,B2)=0,B2,""))
G3: =IF(OR(E3="",F3=""),"",E3+F3/24) | M3: =IF(A3="","",IF(I3<>"","Respondido",IF(G3="","Sem prazo definido",IF(NOW()>G3,"Prazo encerrado – sem resposta","Aguardando")))) | N3: =IF(B3="","",IF(COUNTIF(B4:B$302,B3)=0,B3,""))
G4: =IF(OR(E4="",F4=""),"",E4+F4/24) | M4: =IF(A4="","",IF(I4<>"","Respondido",IF(G4="","Sem prazo definido",IF(NOW()>G4,"Prazo encerrado – sem resposta","Aguardando")))) | N4: =IF(B4="","",IF(COUNTIF(B5:B$302,B4)=0,B4,""))
G5: =IF(OR(E5="",F5=""),"",E5+F5/24) | M5: =IF(A5="","",IF(I5<>"","Respondido",IF(G5="","Sem prazo definido",IF(NOW()>G5,"Prazo encerrado – sem resposta","Aguardando")))) | N5: =IF(B5="","",IF(COUNTIF(B6:B$302,B5)=0,B5,""))
G6: =IF(OR(E6="",F6=""),"",E6+F6/24) | M6: =IF(A6="","",IF(I6<>"","Respondido",IF(G6="","Sem prazo definido",IF(NOW()>G6,"Prazo encerrado – sem resposta","Aguardando")))) | N6: =IF(B6="","",IF(COUNTIF(B7:B$302,B6)=0,B6,""))
G7: =IF(OR(E7="",F7=""),"",E7+F7/24) | M7: =IF(A7="","",IF(I7<>"","Respondido",IF(G7="","Sem prazo definido",IF(NOW()>G7,"Prazo encerrado – sem resposta","Aguardando")))) | N7: =IF(B7="","",IF(COUNTIF(B8:B$302,B7)=0,B7,""))
G8: =IF(OR(E8="",F8=""),"",E8+F8/24) | M8: =IF(A8="","",IF(I8<>"","Respondido",IF(G8="","Sem prazo definido",IF(NOW()>G8,"Prazo encerrado – sem resposta","Aguardando")))) | N8: =IF(B8="","",IF(COUNTIF(B9:B$302,B8)=0,B8,""))
G9: =IF(OR(E9="",F9=""),"",E9+F9/24) | M9: =IF(A9="","",IF(I9<>"","Respondido",IF(G9="","Sem prazo definido",IF(NOW()>G9,"Prazo encerrado – sem resposta","Aguardando")))) | N9: =IF(B9="","",IF(COUNTIF(B10:B$302,B9)=0,B9,""))
G10: =IF(OR(E10="",F10=""),"",E10+F10/24) | M10: =IF(A10="","",IF(I10<>"","Respondido",IF(G10="","Sem prazo definido",IF(NOW()>G10,"Prazo encerrado – sem resposta","Aguardando")))) | N10: =IF(B10="","",IF(COUNTIF(B11:B$302,B10)=0,B10,""))
G11: =IF(OR(E11="",F11=""),"",E11+F11/24) | M11: =IF(A11="","",IF(I11<>"","Respondido",IF(G11="","Sem prazo definido",IF(NOW()>G11,"Prazo encerrado – sem resposta","Aguardando")))) | N11: =IF(B11="","",IF(COUNTIF(B12:B$302,B11)=0,B11,""))
G12: =IF(OR(E12="",F12=""),"",E12+F12/24) | M12: =IF(A12="","",IF(I12<>"","Respondido",IF(G12="","Sem prazo definido",IF(NOW()>G12,"Prazo encerrado – sem resposta","Aguardando")))) | N12: =IF(B12="","",IF(COUNTIF(B13:B$302,B12)=0,B12,""))
G13: =IF(OR(E13="",F13=""),"",E13+F13/24) | M13: =IF(A13="","",IF(I13<>"","Respondido",IF(G13="","Sem prazo definido",IF(NOW()>G13,"Prazo encerrado – sem resposta","Aguardando")))) | N13: =IF(B13="","",IF(COUNTIF(B14:B$302,B13)=0,B13,""))
G14: =IF(OR(E14="",F14=""),"",E14+F14/24) | M14: =IF(A14="","",IF(I14<>"","Respondido",IF(G14="","Sem prazo definido",IF(NOW()>G14,"Prazo encerrado – sem resposta","Aguardando")))) | N14: =IF(B14="","",IF(COUNTIF(B15:B$302,B14)=0,B14,""))
... G301: =IF(OR(E301="",F301=""),"",E301+F301/24) | M301: =IF(A301="","",IF(I301<>"","Respondido",IF(G301="","Sem prazo definido",IF(NOW()>G301,"Prazo encerrado – sem resposta","Aguardando")))) | N301: =IF(B301="","",IF(COUNTIF(B302:B$302,B301)=0,B301,""))

Sheet Completude
A1: Teste | B1: Conjunto | C1: Item | D1: Situação (módulo F5) | E1: Detalhe | F1: ID conjunto | G1: Explicação documentada? | H1: Tipo de explicação | I1: Referência da explicação (fls.) | J1: Analista | K1: Revisor cego | L1: Revisor ≠ analista? | M1: Status
A2: C1 contas declaradas | B2: bancário | C2: conta 237|3000|555 (IR 2023, EXEMPLO – substituir) | D2: lacuna | E2: conta declarada no IR, dentro do escopo, sem extrato entregue (verificar L2/L3) | F2: CONJ-01 | G2: Não | H2: Nenhuma explicação documentada | J2: M04 | K2: M05 | L2: =IF(K2="","",IF(K2<>J2,"Sim","NÃO")) | M2: =IF(A2="","",IF(AND(D2<>"lacuna",D2<>"verificar"),"Sem pendência",IF(OR(G2="",H2="",K2=""),"Aguarda análise/revisão",IF(L2<>"Sim","NÃO – revisor = analista",IF(H2="Sem lacuna (verificado)","Sem lacuna (verificado)",IF(AND(G2="Sim",LEFT(H2,1)="L"),"Lacuna explicada","Lacuna não explicada"))))))
L3: =IF(K3="","",IF(K3<>J3,"Sim","NÃO")) | M3: =IF(A3="","",IF(AND(D3<>"lacuna",D3<>"verificar"),"Sem pendência",IF(OR(G3="",H3="",K3=""),"Aguarda análise/revisão",IF(L3<>"Sim","NÃO – revisor = analista",IF(H3="Sem lacuna (verificado)","Sem lacuna (verificado)",IF(AND(G3="Sim",LEFT(H3,1)="L"),"Lacuna explicada","Lacuna não explicada"))))))
L4: =IF(K4="","",IF(K4<>J4,"Sim","NÃO")) | M4: =IF(A4="","",IF(AND(D4<>"lacuna",D4<>"verificar"),"Sem pendência",IF(OR(G4="",H4="",K4=""),"Aguarda análise/revisão",IF(L4<>"Sim","NÃO – revisor = analista",IF(H4="Sem lacuna (verificado)","Sem lacuna (verificado)",IF(AND(G4="Sim",LEFT(H4,1)="L"),"Lacuna explicada","Lacuna não explicada"))))))
L5: =IF(K5="","",IF(K5<>J5,"Sim","NÃO")) | M5: =IF(A5="","",IF(AND(D5<>"lacuna",D5<>"verificar"),"Sem pendência",IF(OR(G5="",H5="",K5=""),"Aguarda análise/revisão",IF(L5<>"Sim","NÃO – revisor = analista",IF(H5="Sem lacuna (verificado)","Sem lacuna (verificado)",IF(AND(G5="Sim",LEFT(H5,1)="L"),"Lacuna explicada","Lacuna não explicada"))))))
L6: =IF(K6="","",IF(K6<>J6,"Sim","NÃO")) | M6: =IF(A6="","",IF(AND(D6<>"lacuna",D6<>"verificar"),"Sem pendência",IF(OR(G6="",H6="",K6=""),"Aguarda análise/revisão",IF(L6<>"Sim","NÃO – revisor = analista",IF(H6="Sem lacuna (verificado)","Sem lacuna (verificado)",IF(AND(G6="Sim",LEFT(H6,1)="L"),"Lacuna explicada","Lacuna não explicada"))))))
L7: =IF(K7="","",IF(K7<>J7,"Sim","NÃO")) | M7: =IF(A7="","",IF(AND(D7<>"lacuna",D7<>"verificar"),"Sem pendência",IF(OR(G7="",H7="",K7=""),"Aguarda análise/revisão",IF(L7<>"Sim","NÃO – revisor = analista",IF(H7="Sem lacuna (verificado)","Sem lacuna (verificado)",IF(AND(G7="Sim",LEFT(H7,1)="L"),"Lacuna explicada","Lacuna não explicada"))))))
L8: =IF(K8="","",IF(K8<>J8,"Sim","NÃO")) | M8: =IF(A8="","",IF(AND(D8<>"lacuna",D8<>"verificar"),"Sem pendência",IF(OR(G8="",H8="",K8=""),"Aguarda análise/revisão",IF(L8<>"Sim","NÃO – revisor = analista",IF(H8="Sem lacuna (verificado)","Sem lacuna (verificado)",IF(AND(G8="Sim",LEFT(H8,1)="L"),"Lacuna explicada","Lacuna não explicada"))))))
L9: =IF(K9="","",IF(K9<>J9,"Sim","NÃO")) | M9: =IF(A9="","",IF(AND(D9<>"lacuna",D9<>"verificar"),"Sem pendência",IF(OR(G9="",H9="",K9=""),"Aguarda análise/revisão",IF(L9<>"Sim","NÃO – revisor = analista",IF(H9="Sem lacuna (verificado)","Sem lacuna (verificado)",IF(AND(G9="Sim",LEFT(H9,1)="L"),"Lacuna explicada","Lacuna não explicada"))))))
L10: =IF(K10="","",IF(K10<>J10,"Sim","NÃO")) | M10: =IF(A10="","",IF(AND(D10<>"lacuna",D10<>"verificar"),"Sem pendência",IF(OR(G10="",H10="",K10=""),"Aguarda análise/revisão",IF(L10<>"Sim","NÃO – revisor = analista",IF(H10="Sem lacuna (verificado)","Sem lacuna (verificado)",IF(AND(G10="Sim",LEFT(H10,1)="L"),"Lacuna explicada","Lacuna não explicada"))))))
L11: =IF(K11="","",IF(K11<>J11,"Sim","NÃO")) | M11: =IF(A11="","",IF(AND(D11<>"lacuna",D11<>"verificar"),"Sem pendência",IF(OR(G11="",H11="",K11=""),"Aguarda análise/revisão",IF(L11<>"Sim","NÃO – revisor = analista",IF(H11="Sem lacuna (verificado)","Sem lacuna (verificado)",IF(AND(G11="Sim",LEFT(H11,1)="L"),"Lacuna explicada","Lacuna não explicada"))))))
L12: =IF(K12="","",IF(K12<>J12,"Sim","NÃO")) | M12: =IF(A12="","",IF(AND(D12<>"lacuna",D12<>"verificar"),"Sem pendência",IF(OR(G12="",H12="",K12=""),"Aguarda análise/revisão",IF(L12<>"Sim","NÃO – revisor = analista",IF(H12="Sem lacuna (verificado)","Sem lacuna (verificado)",IF(AND(G12="Sim",LEFT(H12,1)="L"),"Lacuna explicada","Lacuna não explicada"))))))
